Workbook
Name Total_da_Festa_est: Recepção[[#Totals],[ESTIMADO]]
Name Total_da_Festa_real: Recepção[[#Totals],[REAL]]
Name Total_da_Viagem_Transporte_est: Viagem[[#Totals],[ESTIMADO]]
Name Total_de_Decoração_est: Decorações[[#Totals],[ESTIMADO]]
Name Total_de_Decoração_real: Decorações[[#Totals],[REAL]]
Name Total_de_Flores_est: Flores[[#Totals],[ESTIMADO]]
Name Total_de_Flores_real: Flores[[#Totals],[REAL]]
Name Total_de_Fotografia_est: Fotografia[[#Totals],[ESTIMADO]]
Name Total_de_Fotografia_real: Fotografia[[#Totals],[REAL]]
Name Total_de_Impressão_gráfica_est: Impressão[[#Totals],[ESTIMADO]]
Name Total_de_Impressão_gráfica_real: Impressão[[#Totals],[REAL]]
Name Total_de_Música_entretenimento_est: Música[[#Totals],[ESTIMADO]]
Name Total_de_Música_entretenimento_real: Música[[#Totals],[REAL]]
Name Total_de_Outras_despesas_est: OutrasDespesas[[#Totals],[ESTIMADO]]
Name Total_de_Outras_despesas_real: OutrasDespesas[[#Totals],[REAL]]
Name Total_de_Presentes_est: Presentes[[#Totals],[ESTIMADO]]
Name Total_de_Presentes_real: Presentes[[#Totals],[REAL]]
Name Total_de_Roupas_est: Vestuário[[#Totals],[ESTIMADO]]
Name Total_de_Roupas_real: Vestuário[[#Totals],[REAL]]
Name Total_de_Viagem_transporte_real: Viagem[[#Totals],[REAL]]

Sheet Orçamento de casamento
B2: Orçamento do Casamento
B3: Data do casamento: | D3: Dias restantes:
B4: =TODAY()+365 -> 46414 | D4: =B4-TODAY() -> 365
B5: CATEGORIA | C5: ESTIMADO | D5: REAL | E5: ACIMA/ABAIXO
B6: Vestuário | C6: =Total_de_Roupas_est -> 15000 | D6: =Total_de_Roupas_real -> 1500 | E6: =ResumoDoOrçamento[[#This Row],[ESTIMADO]]-ResumoDoOrçamento[[#This Row],[REAL]] -> 13500
B7: Recepção | C7: =Total_da_Festa_est -> 15750 | D7: =Total_da_Festa_real -> 0 | E7: =ResumoDoOrçamento[[#This Row],[ESTIMADO]]-ResumoDoOrçamento[[#This Row],[REAL]] -> 15750
B8: Música | C8: =Total_de_Música_entretenimento_est -> 0 | D8: =Total_de_Música_entretenimento_real -> 400 | E8: =ResumoDoOrçamento[[#This Row],[ESTIMADO]]-ResumoDoOrçamento[[#This Row],[REAL]] -> -400
B9: Impressão | C9: =Total_de_Impressão_gráfica_est -> 0 | D9: =Total_de_Impressão_gráfica_real -> 870 | E9: =ResumoDoOrçamento[[#This Row],[ESTIMADO]]-ResumoDoOrçamento[[#This Row],[REAL]] -> -870
B10: Fotografia | C10: =Total_de_Fotografia_est -> 1625 | D10: =Total_de_Fotografia_real -> 1575 | E10: =ResumoDoOrçamento[[#This Row],[ESTIMADO]]-ResumoDoOrçamento[[#This Row],[REAL]] -> 50
B11: Decorações | C11: =Total_de_Decoração_est -> 25000 | D11: =Total_de_Decoração_real -> 20720 | E11: =ResumoDoOrçamento[[#This Row],[ESTIMADO]]-ResumoDoOrçamento[[#This Row],[REAL]] -> 4280
B12: Flores | C12: =Total_de_Flores_est -> 0 | D12: =Total_de_Flores_real -> 850 | E12: =ResumoDoOrçamento[[#This Row],[ESTIMADO]]-ResumoDoOrçamento[[#This Row],[REAL]] -> -850
B13: Presentes | C13: =Total_de_Presentes_est -> 0 | D13: =Total_de_Presentes_real -> 0 | E13: =ResumoDoOrçamento[[#This Row],[ESTIMADO]]-ResumoDoOrçamento[[#This Row],[REAL]] -> 0
B14: Viagem | C14: =Total_da_Viagem_Transporte_est -> 0 | D14: =Total_de_Viagem_transporte_real -> 0 | E14: =ResumoDoOrçamento[[#This Row],[ESTIMADO]]-ResumoDoOrçamento[[#This Row],[REAL]] -> 0
B15: Outros | C15: =Total_de_Outras_despesas_est -> 2500 | D15: =Total_de_Outras_despesas_real -> 0 | E15: =ResumoDoOrçamento[[#This Row],[ESTIMADO]]-ResumoDoOrçamento[[#This Row],[REAL]] -> 2500
B16: Despesas totais | C16: =SUBTOTAL(109,ResumoDoOrçamento[ESTIMADO]) -> 59875 | D16: =SUBTOTAL(109,ResumoDoOrçamento[REAL]) -> 25915 | E16: =SUBTOTAL(109,ResumoDoOrçamento[ACIMA/ABAIXO]) -> 33960

Sheet Despesas
B2: Despesas
B3: VESTUÁRIO
B4: CATEGORIA | C4: ESTIMADO | D4: REAL | E4: ACIMA/ABAIXO/RESTANTE
B5: Anel(is) de noivado | C5: 1500 | D5: 1500 | E5: =Despesas!$C5-Despesas!$D5 -> 0
B6: Alianças | C6: 3500 | D6: 0 | E6: =Despesas!$C6-Despesas!$D6 -> 3500
B7: Traje/smoking do cônjuge 1 | C7: 3000 | D7: 0 | E7: =Despesas!$C7-Despesas!$D7 -> 3000
B8: Vestido | C8: 7000 | D8: 0 | E8: =Despesas!$C8-Despesas!$D8 -> 7000
B9: Sapatos do cônjuge 1 | C9: 0 | D9: 0 | E9: =Despesas!$C9-Despesas!$D9 -> 0
B10: Joias do cônjuge 1 | C10: 0 | D10: 0 | E10: =Despesas!$C10-Despesas!$D10 -> 0
B11: Meias do cônjuge 1 | C11: 0 | D11: 0 | E11: =Despesas!$C11-Despesas!$D11 -> 0
B12: Anel do cônjuge 2 | C12: 0 | D12: 0 | E12: =Despesas!$C12-Despesas!$D12 -> 0
B13: Traje/smoking do cônjuge 2 | C13: 0 | D13: 0 | E13: =Despesas!$C13-Despesas!$D13 -> 0
B14: Véu/tiara do cônjuge 2 | C14: 0 | D14: 0 | E14: =Despesas!$C14-Despesas!$D14 -> 0
B15: Sapatos do cônjuge 2 | C15: 0 | D15: 0 | E15: =Despesas!$C15-Despesas!$D15 -> 0
B16: Joias do cônjuge 2 | C16: 0 | D16: 0 | E16: =Despesas!$C16-Despesas!$D16 -> 0
B17: Meias do cônjuge 2 | C17: 0 | D17: 0 | E17: =Despesas!$C17-Despesas!$D17 -> 0
B18: Total das roupas | C18: =SUBTOTAL(109,Vestuário[ESTIMADO]) -> 15000 | D18: =SUBTOTAL(109,Vestuário[REAL]) -> 1500 | E18: =SUBTOTAL(109,Vestuário[ACIMA/ABAIXO/RESTANTE]) -> 13500
B19: RECEPÇÃO*
B20: CATEGORIA | C20: ESTIMADO | D20: REAL | E20: ACIMA/ABAIXO/RESTANTE
B21: Taxas de salas/salão | C21: 2000 | D21: 0 | E21: =Despesas!$C21-Despesas!$D21 -> 2000
B22: Mesas e cadeiras | C22: 0 | D22: 0 | E22: =Despesas!$C22-Despesas!$D22 -> 0
B23: Alimentação | C23: 13750 | D23: 0 | E23: =Despesas!$C23-Despesas!$D23 -> 13750
B24: Bebidas | C24: 0 | D24: 0 | E24: =Despesas!$C24-Despesas!$D24 -> 0
B25: Roupa de mesa | C25: 0 | D25: 0 | E25: =Despesas!$C25-Despesas!$D25 -> 0
B26: Bolo | C26: 0 | D26: 0 | E26: =Despesas!$C26-Despesas!$D26 -> 0
B27: Lembranças | C27: 0 | D27: 0 | E27: =Despesas!$C27-Despesas!$D27 -> 0
B28: Funcionários e gorjetas | C28: 0 | D28: 0 | E28: =Despesas!$C28-Despesas!$D28 -> 0
B29: Total da festa | C29: =SUBTOTAL(109,Recepção[ESTIMADO]) -> 15750 | D29: =SUBTOTAL(109,Recepção[REAL]) -> 0 | E29: =SUBTOTAL(109,Recepção[ACIMA/ABAIXO/RESTANTE]) -> 15750
B30: * Exceto decoração e entretenimento
B31: MÚSICA/ENTRETENIMENTO
B32: CATEGORIA | C32: ESTIMADO | D32: REAL | E32: ACIMA/ABAIXO/RESTANTE
B33: Músicos para a cerimônia | C33: 0 | D33: 400 | E33: =Despesas!$C33-Despesas!$D33 -> -400
B34: Banda/DJ para a festa | C34: 0 | D34: 0 | E34: =Despesas!$C34-Despesas!$D34 -> 0
B35: Total de música/entretenimento | C35: =SUBTOTAL(109,Música[ESTIMADO]) -> 0 | D35: =SUBTOTAL(109,Música[REAL]) -> 400 | E35: =SUBTOTAL(109,Música[ACIMA/ABAIXO/RESTANTE]) -> -400
B36: PINTURA/PAPELARIA
B37: CATEGORIA | C37: ESTIMADO | D37: REAL | E37: ACIMA/ABAIXO/RESTANTE
B38: Convites | C38: 0 | D38: 450 | E38: =Despesas!$C38-Despesas!$D38 -> -450
B39: Comunicados | C39: 0 | D39: 175 | E39: =Despesas!$C39-Despesas!$D39 -> -175
B40: Cartões de agradecimento | C40: 0 | D40: 100 | E40: =Despesas!$C40-Despesas!$D40 -> -100
B41: Papel de carta pessoal | C41: 0 | D41: 0 | E41: =Despesas!$C41-Despesas!$D41 -> 0
...
